<?xml version="1.0"?>
<robot xmlns:xacro="http://www.ros.org/wiki/xacro"  >

    <xacro:include filename="inertial_macros.xacro"/>

    <material name="white">
        <color rgba="1 1 1 1" />
    </material>

    <material name="orange">
        <color rgba="1 0.3 0.1 1" />
    </material>

    <material name="blue">
        <color rgba="0.2 0.2 1 1" />
    </material>

    <material name="black">
        <color rgba="0 0 0 1" />
    </material>

    <material name="red">
        <color rgba="1 0 0 0" />
    </material>

        <material name="green">
        <color rgba="0 1 0 0" />
    </material>
    
    <!-- BASE LINK -->

    <link name="base_link">
        
    </link>

    <!-- BASE_FOOTPRINT LINK -->

    <joint name="base_footprint_joint" type="fixed">
        <parent link="base_link"/>
        <child link="base_footprint"/>
        <origin xyz="0 0 0" rpy="0 0 0"/>
    </joint>

    <link name="base_footprint">
        
    </link>

    <!-- CHASSIS LINK -->
    <joint name="chassis_joint" type="fixed">
        <parent link="base_link"/>
        <child link="chassis"/>
        <origin xyz="-0.05999 0 0"/>
    </joint>

    <link name="chassis">
        <visual>
            <origin xyz="0.1125 0 0.037505"/>
            <geometry>
                <box size="0.225 0.225 0.07501"/>    
            </geometry>
            <material name="blue"/>
        </visual>
        <collision>
            <origin xyz="0.1125 0 0.037505"/>
            <geometry>
                <box size="0.225 0.225 0.07501"/>    
            </geometry>
        </collision>
        <xacro:inertial_box mass="0.5" x="0.225" y="0.225" z="0.07501">
            <origin xyz="0.1125 0 0.037505" rpy="0 0 0"/>
        </xacro:inertial_box>
    </link>

    <gazebo reference="chassis">
        <material>Gazebo/Blue</material>
    </gazebo>

    <!-- LEFT WHEEL LINK -->

    <joint name="left_wheel_joint" type="continuous">
        <parent link="base_link"/>
        <child link="left_wheel"/>
        <origin xyz="0 0.11975 0" rpy ="-${pi/2} 0 0"/>
        <axis xyz="0 0 1"/>
    </joint>


    <link name="left_wheel">
        <visual>
            <geometry>
                <cylinder radius="0.04" length="0.01"/>
            </geometry>
            <material name="black"/>
        </visual>
        <collision>
            <geometry>
                <cylinder radius="0.04" length="0.01"/>
            </geometry>
        </collision>
        <xacro:inertial_cylinder mass="0.1" length="0.01" radius="0.04">
            <origin xyz="0 0 0" rpy="0 0 0"/>
        </xacro:inertial_cylinder>
    </link>

    <gazebo reference="left_wheel">
        <material>Gazebo/Black</material>
    </gazebo>

    <!-- RIGHT WHEEL LINK -->

    <joint name="right_wheel_joint" type="continuous">
        <parent link="base_link"/>
        <child link="right_wheel"/>
        <origin xyz="0 -0.11975 0" rpy ="${pi/2} 0 0"/>
        <axis xyz="0 0 -1"/>
    </joint>


    <link name="right_wheel">
        <visual>
            <geometry>
                <cylinder radius="0.04" length="0.01"/>
            </geometry>
            <material name="black"/>
        </visual>
        <collision>
            <geometry>
                <cylinder radius="0.04" length="0.01"/>
            </geometry>
        </collision>
        <xacro:inertial_cylinder mass="0.1" length="0.01" radius="0.04">
            <origin xyz="0 0 0" rpy="0 0 0"/>
        </xacro:inertial_cylinder>
    </link>

    <gazebo reference="right_wheel">
        <material>Gazebo/Black</material>
    </gazebo>


    <!-- CASTER WHEEL LINK -->

    <joint name="caster_wheel_joint" type="fixed">
        <parent link="chassis"/>
        <child link="caster_wheel"/>
        <origin xyz="0.16875 0 0"/>
    </joint>


    <link name="caster_wheel">
        <visual>
            <geometry>
                <sphere radius="0.04"/>
            </geometry>
            <material name="white"/>
        </visual>
        <collision>
            <geometry>
                <sphere radius="0.04"/>
            </geometry>
        </collision>
        <!-- Ensure that you validate the masses -->
        <xacro:inertial_sphere mass="0.1" radius="0.04"> 
            <origin xyz="0 0 0" rpy="0 0 0"/>
        </xacro:inertial_sphere>
    </link>

    <gazebo reference="caster_wheel">
        <material>Gazebo/White</material>
        <mu1 value="0.001"/>
        <mu2 value="0.001"/>
    </gazebo>


</robot>